Workbook

Sheet Summary
A1: DemoBlaze – Test Case Suite (Login & Cart)
A3: Application | B3: https://www.demoblaze.com
A4: Scope | B4: Login, Cart, Place Order
A5: Prepared by | B5: QA Automation candidate
A6: Date | B6: 14/10/2026
A7: Test types | B7: Functional, Edge, Negative
A9: Module / Type | B9: Functional | C9: Edge | D9: Negative | E9: Total | F9: Automated
A10: Login | B10: =COUNTIFS('Test Cases'!$B$2:$B$55,"Login",'Test Cases'!$E$2:$E$55,"Functional") -> 6 | C10: =COUNTIFS('Test Cases'!$B$2:$B$55,"Login",'Test Cases'!$E$2:$E$55,"Edge") -> 7 | D10: =COUNTIFS('Test Cases'!$B$2:$B$55,"Login",'Test Cases'!$E$2:$E$55,"Negative") -> 9 | E10: =SUM(B10:D10) -> 22 | F10: =COUNTIFS('Test Cases'!$B$2:$B$55,"Login",'Test Cases'!$M$2:$M$55,"Yes*") -> 12
A11: Cart & Place Order | B11: =COUNTIFS('Test Cases'!$B$2:$B$55,"Cart",'Test Cases'!$E$2:$E$55,"Functional") -> 12 | C11: =COUNTIFS('Test Cases'!$B$2:$B$55,"Cart",'Test Cases'!$E$2:$E$55,"Edge") -> 11 | D11: =COUNTIFS('Test Cases'!$B$2:$B$55,"Cart",'Test Cases'!$E$2:$E$55,"Negative") -> 9 | E11: =SUM(B11:D11) -> 32 | F11: =COUNTIFS('Test Cases'!$B$2:$B$55,"Cart",'Test Cases'!$M$2:$M$55,"Yes*") -> 16
A12: Total | B12: =SUM(B10:B11) -> 18 | C12: =SUM(C10:C11) -> 18 | D12: =SUM(D10:D11) -> 18 | E12: =SUM(E10:E11) -> 54 | F12: =SUM(F10:F11) -> 28
A14: Automation coverage | B14: =IF(E12=0,0,F12/E12) -> 0.51851852
A16: Execution status
A17: Pass | B17: =COUNTIF('Test Cases'!$L$2:$L$55,"Pass") -> 0
A18: Fail | B18: =COUNTIF('Test Cases'!$L$2:$L$55,"Fail") -> 0
A19: Blocked | B19: =COUNTIF('Test Cases'!$L$2:$L$55,"Blocked") -> 0
A20: Skipped | B20: =COUNTIF('Test Cases'!$L$2:$L$55,"Skipped") -> 0
A21: Not Run | B21: =COUNTIF('Test Cases'!$L$2:$L$55,"Not Run") -> 54
A23: How to use
A24: • Yellow cells in 'Test Cases' (Actual Result, Status) are filled during execution.
A25: • Status uses a dropdown: Not Run / Pass / Fail / Blocked / Skipped. Counts above update automatically.
A26: • 'Automated' maps each case to its Playwright spec in the GitHub repository.
A27: • Notes marked 'Potential defect' are behaviours commonly reported for DemoBlaze; confirm during execution.
A28: • Priority: High = core flow / security, Medium = important variation, Low = cosmetic or rare.

Sheet Test Cases
A1: TC ID | B1: Module | C1: Feature | D1: Test Scenario | E1: Type | F1: Priority | G1: Preconditions | H1: Test Steps | I1: Test Data | J1: Expected Result | K1: Actual Result | L1: Status | M1: Automated | N1: Notes
A2: TC_LOGIN_01 | B2: Login | C2: Login | D2: Login with valid credentials | E2: Functional | F2: High | G2: A registered account exists (U1 / P1) | H2: 1. Open https://www.demoblaze.com 2. Click 'Log in' in the navbar 3. Enter valid username and password 4. Click 'Log in' | I2: Username: U1 Password: P1 | J2: Modal closes. Navbar shows 'Welcome U1' and 'Log out'. 'Log in' and 'Sign up' are hidden. | L2: Not Run | M2: Yes – tests/ui/login.spec.ts (desktop + mobile)
A3: TC_LOGIN_02 | B3: Login | C3: Session | D3: Session persists after page reload | E3: Functional | F3: Medium | G3: A registered account exists (U1 / P1) | H3: 1. Log in as U1 2. Reload the page (F5) | I3: U1 / P1 | J3: User stays logged in; 'Welcome U1' still displayed. | L3: Not Run | M3: Yes – login.spec.ts
A4: TC_LOGIN_03 | B4: Login | C4: Logout | D4: Logout returns to guest state | E4: Functional | F4: High | G4: User U1 is logged in | H4: 1. Click 'Log out' | I4: - | J4: 'Log in' and 'Sign up' shown again; 'Welcome' and 'Log out' hidden; session cleared. | L4: Not Run | M4: Yes – login.spec.ts
A5: TC_LOGIN_04 | B5: Login | C5: Login | D5: Username is case-sensitive | E5: Edge | F5: Medium | G5: A registered account exists (U1 / P1) | H5: 1. Open https://www.demoblaze.com 2. Click 'Log in' in the navbar 3. Enter U1 in different letter case with correct password 4. Click 'Log in' | I5: Username: upper-case variant of U1 Password: P1 | J5: Login behaviour is consistent with sign-up rules: a username differing only by case is not treated as U1 (error 'User does not exist.'). | L5: Not Run | M5: No | N5: Clarify expected rule with PO if undocumented.
A6: TC_LOGIN_05 | B6: Login | C6: Login | D6: Login with wrong password | E6: Negative | F6: High | G6: A registered account exists (U1 / P1) | H6: 1. Open https://www.demoblaze.com 2. Click 'Log in' in the navbar 3. Enter valid username, wrong password 4. Click 'Log in' | I6: Username: U1 Password: P1_wrong | J6: Alert 'Wrong password.' is displayed. User is not logged in. | L6: Not Run | M6: Yes – login.spec.ts
A7: TC_LOGIN_06 | B7: Login | C7: Login | D7: Login with non-existent username | E7: Negative | F7: High | G7: - | H7: 1. Open https://www.demoblaze.com 2. Click 'Log in' in the navbar 3. Enter an unregistered username and any password 4. Click 'Log in' | I7: Username: ghost_<random> Password: AnyPassword123 | J7: Alert 'User does not exist.' is displayed. User is not logged in. | L7: Not Run | M7: Yes – login.spec.ts
A8: TC_LOGIN_07 | B8: Login | C8: Validation | D8: Both username and password empty | E8: Negative | F8: High | G8: - | H8: 1. Open https://www.demoblaze.com 2. Click 'Log in' in the navbar 3. Leave both fields empty 4. Click 'Log in' | I8: (empty) / (empty) | J8: Alert 'Please fill out Username and Password.' is displayed. | L8: Not Run | M8: Yes – login.spec.ts
A9: TC_LOGIN_08 | B9: Login | C9: Validation | D9: Username empty, password filled | E9: Negative | F9: High | G9: - | H9: 1. Open https://www.demoblaze.com 2. Click 'Log in' in the navbar 3. Leave username empty, enter password 4. Click 'Log in' | I9: (empty) / Secret123 | J9: Alert 'Please fill out Username and Password.' is displayed. | L9: Not Run | M9: Yes – login.spec.ts
A10: TC_LOGIN_09 | B10: Login | C10: Validation | D10: Username filled, password empty | E10: Negative | F10: High | G10: - | H10: 1. Open https://www.demoblaze.com 2. Click 'Log in' in the navbar 3. Enter username, leave password empty 4. Click 'Log in' | I10: someone / (empty) | J10: Alert 'Please fill out Username and Password.' is displayed. | L10: Not Run | M10: Yes – login.spec.ts
A11: TC_LOGIN_10 | B11: Login | C11: Validation | D11: Leading/trailing spaces around username | E11: Edge | F11: Medium | G11: A registered account exists (U1 / P1) | H11: 1. Open https://www.demoblaze.com 2. Click 'Log in' in the navbar 3. Enter ' U1 ' (spaces) with correct password 4. Click 'Log in' | I11: ' U1 ' / P1 | J11: Input is trimmed and login succeeds, OR a clear error is shown. Behaviour must match sign-up handling. | L11: Not Run | M11: No
A12: TC_LOGIN_11 | B12: Login | C12: Validation | D12: Whitespace-only username and password | E12: Negative | F12: Medium | G12: - | H12: 1. Open https://www.demoblaze.com 2. Click 'Log in' in the navbar 3. Enter only spaces in both fields 4. Click 'Log in' | I12: ' ' / ' ' | J12: Treated as empty: validation alert shown, no login request succeeds. | L12: Not Run | M12: No
A13: TC_LOGIN_12 | B13: Login | C13: Login | D13: Password is case-sensitive | E13: Negative | F13: High | G13: A registered account exists (U1 / P1) | H13: 1. Open https://www.demoblaze.com 2. Click 'Log in' in the navbar 3. Enter U1 and P1 with letter case changed 4. Click 'Log in' | I13: U1 / P1 (case swapped) | J13: Alert 'Wrong password.'; user not logged in. | L13: Not Run | M13: No
A14: TC_LOGIN_13 | B14: Login | C14: Security | D14: Password field is masked | E14: Functional | F14: Medium | G14: - | H14: 1. Open https://www.demoblaze.com 2. Click 'Log in' in the navbar 3. Type a password | I14: Secret123 | J14: Characters are masked (input type='password'). | L14: Not Run | M14: Yes – login.spec.ts
A15: TC_LOGIN_14 | B15: Login | C15: Validation | D15: Very long username / password (255+ chars) | E15: Edge | F15: Low | G15: - | H15: 1. Open https://www.demoblaze.com 2. Click 'Log in' in the navbar 3. Paste 256-character strings into both fields 4. Click 'Log in' | I15: 256 x 'a' | J15: No crash or freeze; field length is limited or a proper error is shown. | L15: Not Run | M15: No
A16: TC_LOGIN_15 | B16: Login | C16: Security | D16: SQL injection payload in credentials | E16: Negative | F16: High | G16: - | H16: 1. Open https://www.demoblaze.com 2. Click 'Log in' in the navbar 3. Enter SQL payload in both fields 4. Click 'Log in' | I16: ' OR '1'='1 | J16: Login is rejected with an error alert; user NOT authenticated; no server error exposed. | L16: Not Run | M16: Yes – login.spec.ts
A17: TC_LOGIN_16 | B17: Login | C17: Login | D17: Close modal without submitting | E17: Functional | F17: Low | G17: A registered account exists (U1 / P1) | H17: 1. Open https://www.demoblaze.com 2. Click 'Log in' in the navbar 3. Enter valid credentials 4. Click 'Close' | I17: U1 / P1 | J17: Modal closes; user remains a guest ('Log in' visible). | L17: Not Run | M17: Yes – login.spec.ts
A18: TC_LOGIN_17 | B18: Login | C18: Security | D18: XSS payload in username | E18: Negative | F18: High | G18: - | H18: 1. Open https://www.demoblaze.com 2. Click 'Log in' in the navbar 3. Enter <script>alert('xss')</script> as username 4. Click 'Log in' | I18: <script>alert('xss')</script> / any | J18: Script is not executed; only the normal error alert appears; payload never rendered as HTML. | L18: Not Run | M18: No
A19: TC_LOGIN_18 | B19: Login | C19: Usability | D19: Submit login with Enter key | E19: Edge | F19: Low | G19: A registered account exists (U1 / P1) | H19: 1. Open https://www.demoblaze.com 2. Click 'Log in' in the navbar 3. Enter credentials 4. Press Enter in password field | I19: U1 / P1 | J19: Form is submitted and user is logged in (keyboard accessibility). | L19: Not Run | M19: No | N19: Potential usability defect if Enter does nothing.
A20: TC_LOGIN_19 | B20: Login | C20: Login | D20: Multiple rapid clicks on 'Log in' button | E20: Edge | F20: Low | G20: A registered account exists (U1 / P1) | H20: 1. Open https://www.demoblaze.com 2. Click 'Log in' in the navbar 3. Enter valid credentials 4. Double/triple-click 'Log in' quickly | I20: U1 / P1 | J20: User logged in once; no duplicate alerts or errors. | L20: Not Run | M20: No
A21: TC_LOGIN_20 | B21: Login | C21: Session | D21: Login state shared across browser tabs | E21: Edge | F21: Low | G21: User U1 logged in, tab A | H21: 1. Open https://www.demoblaze.com in new tab B | I21: - | J21: Tab B shows 'Welcome U1' (same session cookie). | L21: Not Run | M21: No
A22: TC_LOGIN_21 | B22: Login | C22: Login | D22: Unicode / Vietnamese characters in username | E22: Edge | F22: Low | G22: Account 'kiểm_thử' registered | H22: 1. Open https://www.demoblaze.com 2. Click 'Log in' in the navbar 3. Enter unicode username and its password 4. Click 'Log in' | I22: kiểm_thử / P1 | J22: Login succeeds; welcome text renders unicode correctly. | L22: Not Run | M22: No
A23: TC_LOGIN_22 | B23: Login | C23: Cross-platform | D23: Login on mobile viewport (Pixel 7 / iPhone 14) | E23: Functional | F23: Medium | G23: A registered account exists (U1 / P1) | H23: 1. Open site on mobile viewport 2. Open hamburger menu 3. Click 'Log in' and submit valid credentials | I23: U1 / P1 | J23: Same result as TC_LOGIN_01; layout usable on small screen. | L23: Not Run | M23: Yes – mobile-chrome / mobile-safari projects
A24: TC_CART_01 | B24: Cart | C24: Add to cart | D24: Guest adds a product to cart | E24: Functional | F24: High | G24: Not logged in | H24: 1. Open product 'Samsung galaxy s6' 2. Note the price 3. Click 'Add to cart' 4. Accept alert 5. Open 'Cart' | I24: Product id 1 | J24: Alert 'Product added'. Cart shows 1 row with correct title and price; Total = product price. | L24: Not Run | M24: Yes – tests/ui/cart.spec.ts
A25: TC_CART_02 | B25: Cart | C25: Add to cart | D25: Logged-in user adds a product to cart | E25: Functional | F25: High | G25: User logged in, empty cart | H25: 1. Open 'Nokia lumia 1520' 2. Click 'Add to cart' 3. Open 'Cart' | I25: Product id 2 | J25: Product listed once in cart with correct price. | L25: Not Run | M25: Yes – cart.spec.ts
A26: TC_CART_03 | B26: Cart | C26: Total | D26: Products from different categories – total is the sum | E26: Functional | F26: High | G26: User logged in, empty cart | H26: 1. Add a phone, a laptop and a monitor 2. Open 'Cart' | I26: Samsung galaxy s6, Sony vaio i5, Apple monitor 24 | J26: 3 rows displayed; Total = sum of the 3 prices. | L26: Not Run | M26: Yes – cart.spec.ts
A27: TC_CART_04 | B27: Cart | C27: Add to cart | D27: Add the same product twice | E27: Edge | F27: Medium | G27: User logged in, empty cart | H27: 1. Add 'Samsung galaxy s6' 2. Add it again 3. Open 'Cart' | I27: Product id 1 x2 | J27: 2 rows for the product; Total = 2 x price. | L27: Not Run | M27: Yes – cart.spec.ts | N27: No quantity field: each add creates a new line.
A28: TC_CART_05 | B28: Cart | C28: Delete | D28: Delete one item updates list and total | E28: Functional | F28: High | G28: Cart has 2 different products | H28: 1. Open 'Cart' 2. Click 'Delete' on one product | I28: - | J28: Row removed; Total recalculated to remaining item price. | L28: Not Run | M28: Yes – cart.spec.ts
A29: TC_CART_06 | B29: Cart | C29: Delete | D29: Delete the last item leaves empty cart | E29: Edge | F29: Medium | G29: Cart has 1 product | H29: 1. Open 'Cart' 2. Click 'Delete' | I29: - | J29: No rows; Total is empty / 0. | L29: Not Run | M29: Yes – cart.spec.ts
A30: TC_CART_07 | B30: Cart | C30: Persistence | D30: Cart kept on account after logout and login | E30: Functional | F30: High | G30: User logged in | H30: 1. Add a product 2. Log out 3. Log in again with same user 4. Open 'Cart' | I30: Sony vaio i5 | J30: Previously added product still in cart. | L30: Not Run | M30: Yes – cart.spec.ts
A31: TC_CART_08 | B31: Cart | C31: Integration | D31: Item added via API appears in UI cart | E31: Functional | F31: Medium | G31: User exists | H31: 1. Call /addtocart API with user token 2. Log in on UI 3. Open 'Cart' | I31: Product id 2 | J31: Product shown in UI cart (front-end and back-end consistent). | L31: Not Run | M31: Yes – cart.spec.ts
A32: TC_CART_09 | B32: Cart | C32: Persistence | D32: Cart persists after page refresh | E32: Functional | F32: Medium | G32: Cart has 1+ product | H32: 1. Open 'Cart' 2. Reload page | I32: - | J32: Same items and total are shown after reload. | L32: Not Run | M32: No
A33: TC_CART_10 | B33: Cart | C33: Isolation | D33: Carts are isolated between users | E33: Negative | F33: High | G33: Users A and B exist | H33: 1. User A adds a product 2. Log in as user B 3. Open 'Cart' | I33: - | J33: User B does not see user A's items. | L33: Not Run | M33: Yes – tests/api/cart.api.spec.ts (API_CART_02)
A34: TC_CART_11 | B34: Cart | C34: Isolation | D34: Guest cart vs. account cart after login | E34: Edge | F34: Medium | G34: Guest cart has 1 product; user has empty cart | H34: 1. As guest, add a product 2. Log in 3. Open 'Cart' | I34: - | J34: Behaviour is defined and consistent (guest items merged OR clearly not shown). No items lost silently. | L34: Not Run | M34: No | N34: Clarify business rule; record actual behaviour.
A35: TC_CART_12 | B35: Cart | C35: Add to cart | D35: Rapid double-click on 'Add to cart' | E35: Edge | F35: Medium | G35: Empty cart | H35: 1. Open a product 2. Double-click 'Add to cart' quickly 3. Open 'Cart' | I35: - | J35: Number of rows equals number of confirmed 'Product added' alerts; no errors. | L35: Not Run | M35: No
A36: TC_CART_13 | B36: Cart | C36: Add to cart | D36: Add to cart while offline | E36: Negative | F36: Medium | G36: - | H36: 1. Open a product 2. Set browser offline (DevTools) 3. Click 'Add to cart' | I36: - | J36: An error is shown; no 'Product added' message; item not added. | L36: Not Run | M36: No
A37: TC_CART_14 | B37: Cart | C37: UI | D37: Empty cart state | E37: Functional | F37: Low | G37: Fresh user / empty cart | H37: 1. Open 'Cart' | I37: - | J37: Table shows no rows; Total is empty or 0; page does not error. | L37: Not Run | M37: No
A38: TC_CART_15 | B38: Cart | C38: Total | D38: Many items (20) – total and performance | E38: Edge | F38: Low | G38: User logged in | H38: 1. Add 20 products (can be seeded via API) 2. Open 'Cart' | I38: 20 items | J38: All 20 rows load within acceptable time; Total equals sum of prices. | L38: Not Run | M38: No
A39: TC_CART_16 | B39: Cart | C39: Product | D39: Product page with invalid id | E39: Negative | F39: Low | G39: - | H39: 1. Open https://www.demoblaze.com/prod.html?idp_=99999 | I39: idp_=99999 | J39: Friendly 'not found' state; 'Add to cart' cannot add a non-existent product. | L39: Not Run | M39: No
A40: TC_CART_17 | B40: Cart | C40: Delete | D40: Double-click 'Delete' | E40: Edge | F40: Low | G40: Cart has 2 products | H40: 1. Open 'Cart' 2. Double-click 'Delete' on one row | I40: - | J40: Only that one item is removed; no error. | L40: Not Run | M40: No
...
